{
 "cells": [
  {
   "cell_type": "code",
   "execution_count": 1,
   "id": "863cba85-db6f-4dd5-a445-96fec4fa800d",
   "metadata": {},
   "outputs": [],
   "source": [
    "# ! pip install tensorflow"
   ]
  },
  {
   "cell_type": "code",
   "execution_count": 2,
   "id": "14df207d-f352-4ea8-872b-9325bdbc29ff",
   "metadata": {},
   "outputs": [],
   "source": [
    "# ! pip install opencv-python"
   ]
  },
  {
   "cell_type": "code",
   "execution_count": 12,
   "id": "efa57f6d-8f1f-4140-aed2-346f60cbd1d5",
   "metadata": {},
   "outputs": [
    {
     "name": "stderr",
     "output_type": "stream",
     "text": [
      "2024-01-29 02:49:22.027811: W tensorflow/core/framework/op_kernel.cc:1827] UNKNOWN: JIT compilation failed.\n"
     ]
    },
    {
     "ename": "UnknownError",
     "evalue": "Graph execution error:\n\nDetected at node model_2/conv2d_56/Sigmoid defined at (most recent call last):\n  File \"<frozen runpy>\", line 198, in _run_module_as_main\n\n  File \"<frozen runpy>\", line 88, in _run_code\n\n  File \"/home/madanbaduwal/anaconda3/lib/python3.11/site-packages/ipykernel_launcher.py\", line 17, in <module>\n\n  File \"/home/madanbaduwal/anaconda3/lib/python3.11/site-packages/traitlets/config/application.py\", line 992, in launch_instance\n\n  File \"/home/madanbaduwal/anaconda3/lib/python3.11/site-packages/ipykernel/kernelapp.py\", line 736, in start\n\n  File \"/home/madanbaduwal/anaconda3/lib/python3.11/site-packages/tornado/platform/asyncio.py\", line 195, in start\n\n  File \"/home/madanbaduwal/anaconda3/lib/python3.11/asyncio/base_events.py\", line 607, in run_forever\n\n  File \"/home/madanbaduwal/anaconda3/lib/python3.11/asyncio/base_events.py\", line 1922, in _run_once\n\n  File \"/home/madanbaduwal/anaconda3/lib/python3.11/asyncio/events.py\", line 80, in _run\n\n  File \"/home/madanbaduwal/anaconda3/lib/python3.11/site-packages/ipykernel/kernelbase.py\", line 516, in dispatch_queue\n\n  File \"/home/madanbaduwal/anaconda3/lib/python3.11/site-packages/ipykernel/kernelbase.py\", line 505, in process_one\n\n  File \"/home/madanbaduwal/anaconda3/lib/python3.11/site-packages/ipykernel/kernelbase.py\", line 412, in dispatch_shell\n\n  File \"/home/madanbaduwal/anaconda3/lib/python3.11/site-packages/ipykernel/kernelbase.py\", line 740, in execute_request\n\n  File \"/home/madanbaduwal/anaconda3/lib/python3.11/site-packages/ipykernel/ipkernel.py\", line 422, in do_execute\n\n  File \"/home/madanbaduwal/anaconda3/lib/python3.11/site-packages/ipykernel/zmqshell.py\", line 546, in run_cell\n\n  File \"/home/madanbaduwal/anaconda3/lib/python3.11/site-packages/IPython/core/interactiveshell.py\", line 3051, in run_cell\n\n  File \"/home/madanbaduwal/anaconda3/lib/python3.11/site-packages/IPython/core/interactiveshell.py\", line 3106, in _run_cell\n\n  File \"/home/madanbaduwal/anaconda3/lib/python3.11/site-packages/IPython/core/async_helpers.py\", line 129, in _pseudo_sync_runner\n\n  File \"/home/madanbaduwal/anaconda3/lib/python3.11/site-packages/IPython/core/interactiveshell.py\", line 3311, in run_cell_async\n\n  File \"/home/madanbaduwal/anaconda3/lib/python3.11/site-packages/IPython/core/interactiveshell.py\", line 3493, in run_ast_nodes\n\n  File \"/home/madanbaduwal/anaconda3/lib/python3.11/site-packages/IPython/core/interactiveshell.py\", line 3553, in run_code\n\n  File \"/tmp/ipykernel_35059/527155597.py\", line 35, in <module>\n\n  File \"/home/madanbaduwal/anaconda3/lib/python3.11/site-packages/keras/src/utils/traceback_utils.py\", line 65, in error_handler\n\n  File \"/home/madanbaduwal/anaconda3/lib/python3.11/site-packages/keras/src/engine/training.py\", line 2655, in predict\n\n  File \"/home/madanbaduwal/anaconda3/lib/python3.11/site-packages/keras/src/engine/training.py\", line 2440, in predict_function\n\n  File \"/home/madanbaduwal/anaconda3/lib/python3.11/site-packages/keras/src/engine/training.py\", line 2425, in step_function\n\n  File \"/home/madanbaduwal/anaconda3/lib/python3.11/site-packages/keras/src/engine/training.py\", line 2413, in run_step\n\n  File \"/home/madanbaduwal/anaconda3/lib/python3.11/site-packages/keras/src/engine/training.py\", line 2381, in predict_step\n\n  File \"/home/madanbaduwal/anaconda3/lib/python3.11/site-packages/keras/src/utils/traceback_utils.py\", line 65, in error_handler\n\n  File \"/home/madanbaduwal/anaconda3/lib/python3.11/site-packages/keras/src/engine/training.py\", line 590, in __call__\n\n  File \"/home/madanbaduwal/anaconda3/lib/python3.11/site-packages/keras/src/utils/traceback_utils.py\", line 65, in error_handler\n\n  File \"/home/madanbaduwal/anaconda3/lib/python3.11/site-packages/keras/src/engine/base_layer.py\", line 1149, in __call__\n\n  File \"/home/madanbaduwal/anaconda3/lib/python3.11/site-packages/keras/src/utils/traceback_utils.py\", line 96, in error_handler\n\n  File \"/home/madanbaduwal/anaconda3/lib/python3.11/site-packages/keras/src/engine/functional.py\", line 515, in call\n\n  File \"/home/madanbaduwal/anaconda3/lib/python3.11/site-packages/keras/src/engine/functional.py\", line 672, in _run_internal_graph\n\n  File \"/home/madanbaduwal/anaconda3/lib/python3.11/site-packages/keras/src/utils/traceback_utils.py\", line 65, in error_handler\n\n  File \"/home/madanbaduwal/anaconda3/lib/python3.11/site-packages/keras/src/engine/base_layer.py\", line 1149, in __call__\n\n  File \"/home/madanbaduwal/anaconda3/lib/python3.11/site-packages/keras/src/utils/traceback_utils.py\", line 96, in error_handler\n\n  File \"/home/madanbaduwal/anaconda3/lib/python3.11/site-packages/keras/src/layers/convolutional/base_conv.py\", line 321, in call\n\n  File \"/home/madanbaduwal/anaconda3/lib/python3.11/site-packages/keras/src/activations.py\", line 400, in sigmoid\n\n  File \"/home/madanbaduwal/anaconda3/lib/python3.11/site-packages/keras/src/backend.py\", line 5915, in sigmoid\n\nJIT compilation failed.\n\t [[{{node model_2/conv2d_56/Sigmoid}}]] [Op:__inference_predict_function_16012]",
     "output_type": "error",
     "traceback": [
      "\u001b[0;31m---------------------------------------------------------------------------\u001b[0m",
      "\u001b[0;31mUnknownError\u001b[0m                              Traceback (most recent call last)",
      "Cell \u001b[0;32mIn[12], line 35\u001b[0m\n\u001b[1;32m     33\u001b[0m img \u001b[38;5;241m=\u001b[39m img \u001b[38;5;241m/\u001b[39m \u001b[38;5;241m255\u001b[39m\n\u001b[1;32m     34\u001b[0m img \u001b[38;5;241m=\u001b[39m img[np\u001b[38;5;241m.\u001b[39mnewaxis, :, :, :]\n\u001b[0;32m---> 35\u001b[0m pred\u001b[38;5;241m=\u001b[39mmodel\u001b[38;5;241m.\u001b[39mpredict(img)\n\u001b[1;32m     37\u001b[0m plt\u001b[38;5;241m.\u001b[39mfigure(figsize\u001b[38;5;241m=\u001b[39m(\u001b[38;5;241m12\u001b[39m,\u001b[38;5;241m12\u001b[39m))\n\u001b[1;32m     38\u001b[0m plt\u001b[38;5;241m.\u001b[39msubplot(\u001b[38;5;241m1\u001b[39m,\u001b[38;5;241m2\u001b[39m,\u001b[38;5;241m1\u001b[39m)\n",
      "File \u001b[0;32m~/anaconda3/lib/python3.11/site-packages/keras/src/utils/traceback_utils.py:70\u001b[0m, in \u001b[0;36mfilter_traceback.<locals>.error_handler\u001b[0;34m(*args, **kwargs)\u001b[0m\n\u001b[1;32m     67\u001b[0m     filtered_tb \u001b[38;5;241m=\u001b[39m _process_traceback_frames(e\u001b[38;5;241m.\u001b[39m__traceback__)\n\u001b[1;32m     68\u001b[0m     \u001b[38;5;66;03m# To get the full stack trace, call:\u001b[39;00m\n\u001b[1;32m     69\u001b[0m     \u001b[38;5;66;03m# `tf.debugging.disable_traceback_filtering()`\u001b[39;00m\n\u001b[0;32m---> 70\u001b[0m     \u001b[38;5;28;01mraise\u001b[39;00m e\u001b[38;5;241m.\u001b[39mwith_traceback(filtered_tb) \u001b[38;5;28;01mfrom\u001b[39;00m \u001b[38;5;28;01mNone\u001b[39;00m\n\u001b[1;32m     71\u001b[0m \u001b[38;5;28;01mfinally\u001b[39;00m:\n\u001b[1;32m     72\u001b[0m     \u001b[38;5;28;01mdel\u001b[39;00m filtered_tb\n",
      "File \u001b[0;32m~/anaconda3/lib/python3.11/site-packages/tensorflow/python/eager/execute.py:53\u001b[0m, in \u001b[0;36mquick_execute\u001b[0;34m(op_name, num_outputs, inputs, attrs, ctx, name)\u001b[0m\n\u001b[1;32m     51\u001b[0m \u001b[38;5;28;01mtry\u001b[39;00m:\n\u001b[1;32m     52\u001b[0m   ctx\u001b[38;5;241m.\u001b[39mensure_initialized()\n\u001b[0;32m---> 53\u001b[0m   tensors \u001b[38;5;241m=\u001b[39m pywrap_tfe\u001b[38;5;241m.\u001b[39mTFE_Py_Execute(ctx\u001b[38;5;241m.\u001b[39m_handle, device_name, op_name,\n\u001b[1;32m     54\u001b[0m                                       inputs, attrs, num_outputs)\n\u001b[1;32m     55\u001b[0m \u001b[38;5;28;01mexcept\u001b[39;00m core\u001b[38;5;241m.\u001b[39m_NotOkStatusException \u001b[38;5;28;01mas\u001b[39;00m e:\n\u001b[1;32m     56\u001b[0m   \u001b[38;5;28;01mif\u001b[39;00m name \u001b[38;5;129;01mis\u001b[39;00m \u001b[38;5;129;01mnot\u001b[39;00m \u001b[38;5;28;01mNone\u001b[39;00m:\n",
      "\u001b[0;31mUnknownError\u001b[0m: Graph execution error:\n\nDetected at node model_2/conv2d_56/Sigmoid defined at (most recent call last):\n  File \"<frozen runpy>\", line 198, in _run_module_as_main\n\n  File \"<frozen runpy>\", line 88, in _run_code\n\n  File \"/home/madanbaduwal/anaconda3/lib/python3.11/site-packages/ipykernel_launcher.py\", line 17, in <module>\n\n  File \"/home/madanbaduwal/anaconda3/lib/python3.11/site-packages/traitlets/config/application.py\", line 992, in launch_instance\n\n  File \"/home/madanbaduwal/anaconda3/lib/python3.11/site-packages/ipykernel/kernelapp.py\", line 736, in start\n\n  File \"/home/madanbaduwal/anaconda3/lib/python3.11/site-packages/tornado/platform/asyncio.py\", line 195, in start\n\n  File \"/home/madanbaduwal/anaconda3/lib/python3.11/asyncio/base_events.py\", line 607, in run_forever\n\n  File \"/home/madanbaduwal/anaconda3/lib/python3.11/asyncio/base_events.py\", line 1922, in _run_once\n\n  File \"/home/madanbaduwal/anaconda3/lib/python3.11/asyncio/events.py\", line 80, in _run\n\n  File \"/home/madanbaduwal/anaconda3/lib/python3.11/site-packages/ipykernel/kernelbase.py\", line 516, in dispatch_queue\n\n  File \"/home/madanbaduwal/anaconda3/lib/python3.11/site-packages/ipykernel/kernelbase.py\", line 505, in process_one\n\n  File \"/home/madanbaduwal/anaconda3/lib/python3.11/site-packages/ipykernel/kernelbase.py\", line 412, in dispatch_shell\n\n  File \"/home/madanbaduwal/anaconda3/lib/python3.11/site-packages/ipykernel/kernelbase.py\", line 740, in execute_request\n\n  File \"/home/madanbaduwal/anaconda3/lib/python3.11/site-packages/ipykernel/ipkernel.py\", line 422, in do_execute\n\n  File \"/home/madanbaduwal/anaconda3/lib/python3.11/site-packages/ipykernel/zmqshell.py\", line 546, in run_cell\n\n  File \"/home/madanbaduwal/anaconda3/lib/python3.11/site-packages/IPython/core/interactiveshell.py\", line 3051, in run_cell\n\n  File \"/home/madanbaduwal/anaconda3/lib/python3.11/site-packages/IPython/core/interactiveshell.py\", line 3106, in _run_cell\n\n  File \"/home/madanbaduwal/anaconda3/lib/python3.11/site-packages/IPython/core/async_helpers.py\", line 129, in _pseudo_sync_runner\n\n  File \"/home/madanbaduwal/anaconda3/lib/python3.11/site-packages/IPython/core/interactiveshell.py\", line 3311, in run_cell_async\n\n  File \"/home/madanbaduwal/anaconda3/lib/python3.11/site-packages/IPython/core/interactiveshell.py\", line 3493, in run_ast_nodes\n\n  File \"/home/madanbaduwal/anaconda3/lib/python3.11/site-packages/IPython/core/interactiveshell.py\", line 3553, in run_code\n\n  File \"/tmp/ipykernel_35059/527155597.py\", line 35, in <module>\n\n  File \"/home/madanbaduwal/anaconda3/lib/python3.11/site-packages/keras/src/utils/traceback_utils.py\", line 65, in error_handler\n\n  File \"/home/madanbaduwal/anaconda3/lib/python3.11/site-packages/keras/src/engine/training.py\", line 2655, in predict\n\n  File \"/home/madanbaduwal/anaconda3/lib/python3.11/site-packages/keras/src/engine/training.py\", line 2440, in predict_function\n\n  File \"/home/madanbaduwal/anaconda3/lib/python3.11/site-packages/keras/src/engine/training.py\", line 2425, in step_function\n\n  File \"/home/madanbaduwal/anaconda3/lib/python3.11/site-packages/keras/src/engine/training.py\", line 2413, in run_step\n\n  File \"/home/madanbaduwal/anaconda3/lib/python3.11/site-packages/keras/src/engine/training.py\", line 2381, in predict_step\n\n  File \"/home/madanbaduwal/anaconda3/lib/python3.11/site-packages/keras/src/utils/traceback_utils.py\", line 65, in error_handler\n\n  File \"/home/madanbaduwal/anaconda3/lib/python3.11/site-packages/keras/src/engine/training.py\", line 590, in __call__\n\n  File \"/home/madanbaduwal/anaconda3/lib/python3.11/site-packages/keras/src/utils/traceback_utils.py\", line 65, in error_handler\n\n  File \"/home/madanbaduwal/anaconda3/lib/python3.11/site-packages/keras/src/engine/base_layer.py\", line 1149, in __call__\n\n  File \"/home/madanbaduwal/anaconda3/lib/python3.11/site-packages/keras/src/utils/traceback_utils.py\", line 96, in error_handler\n\n  File \"/home/madanbaduwal/anaconda3/lib/python3.11/site-packages/keras/src/engine/functional.py\", line 515, in call\n\n  File \"/home/madanbaduwal/anaconda3/lib/python3.11/site-packages/keras/src/engine/functional.py\", line 672, in _run_internal_graph\n\n  File \"/home/madanbaduwal/anaconda3/lib/python3.11/site-packages/keras/src/utils/traceback_utils.py\", line 65, in error_handler\n\n  File \"/home/madanbaduwal/anaconda3/lib/python3.11/site-packages/keras/src/engine/base_layer.py\", line 1149, in __call__\n\n  File \"/home/madanbaduwal/anaconda3/lib/python3.11/site-packages/keras/src/utils/traceback_utils.py\", line 96, in error_handler\n\n  File \"/home/madanbaduwal/anaconda3/lib/python3.11/site-packages/keras/src/layers/convolutional/base_conv.py\", line 321, in call\n\n  File \"/home/madanbaduwal/anaconda3/lib/python3.11/site-packages/keras/src/activations.py\", line 400, in sigmoid\n\n  File \"/home/madanbaduwal/anaconda3/lib/python3.11/site-packages/keras/src/backend.py\", line 5915, in sigmoid\n\nJIT compilation failed.\n\t [[{{node model_2/conv2d_56/Sigmoid}}]] [Op:__inference_predict_function_16012]"
     ]
    }
   ],
   "source": [
    "from tensorflow.keras.models import Model, load_model, save_model\n",
    "import cv2\n",
    "import numpy as np\n",
    "import matplotlib.pyplot as plt\n",
    "from tensorflow.keras import backend as K\n",
    "\n",
    "smooth=100\n",
    "\n",
    "def dice_coef(y_true, y_pred):\n",
    "    y_truef=K.flatten(y_true)\n",
    "    y_predf=K.flatten(y_pred)\n",
    "    And=K.sum(y_truef* y_predf)\n",
    "    return((2* And + smooth) / (K.sum(y_truef) + K.sum(y_predf) + smooth))\n",
    "\n",
    "def dice_coef_loss(y_true, y_pred):\n",
    "    return -dice_coef(y_true, y_pred)\n",
    "\n",
    "def iou(y_true, y_pred):\n",
    "    intersection = K.sum(y_true * y_pred)\n",
    "    sum_ = K.sum(y_true + y_pred)\n",
    "    jac = (intersection + smooth) / (sum_ - intersection + smooth)\n",
    "    return jac\n",
    "model = load_model('./unet_brain_mri_seg.hdf5', custom_objects={'dice_coef_loss': dice_coef_loss, 'iou': iou, 'dice_coef': dice_coef})\n",
    "\n",
    "\n",
    "\n",
    "#Set Parameters\n",
    "im_width = 256\n",
    "im_height = 256\n",
    "\n",
    "img = cv2.imread('./image.png')\n",
    "img = cv2.resize(img ,(im_height, im_width))\n",
    "img = img / 255\n",
    "img = img[np.newaxis, :, :, :]\n",
    "pred=model.predict(img)\n",
    "\n",
    "plt.figure(figsize=(12,12))\n",
    "plt.subplot(1,2,1)\n",
    "plt.imshow(np.squeeze(img))\n",
    "plt.title('Original Image')\n",
    "plt.subplot(1,2,2)\n",
    "plt.imshow(np.squeeze(pred) > .5)\n",
    "plt.title('Prediction')\n",
    "plt.show()"
   ]
  },
  {
   "cell_type": "code",
   "execution_count": null,
   "id": "8a0013e0-e3ff-4750-9bc0-38ce8378dd0b",
   "metadata": {},
   "outputs": [],
   "source": []
  }
 ],
 "metadata": {
  "kernelspec": {
   "display_name": "Python 3 (ipykernel)",
   "language": "python",
   "name": "python3"
  },
  "language_info": {
   "codemirror_mode": {
    "name": "ipython",
    "version": 3
   },
   "file_extension": ".py",
   "mimetype": "text/x-python",
   "name": "python",
   "nbconvert_exporter": "python",
   "pygments_lexer": "ipython3",
   "version": "3.11.5"
  }
 },
 "nbformat": 4,
 "nbformat_minor": 5
}
